<?xml version="1.0"?>

<robot xmlns:sensor="http://playerstage.sourceforge.net/gazebo/xmlschema/#sensor"
       xmlns:controller="http://playerstage.sourceforge.net/gazebo/xmlschema/#controller"
       xmlns:interface="http://playerstage.sourceforge.net/gazebo/xmlschema/#interface"
       xmlns:xacro="http://ros.org/wiki/xacro"
>
<xacro:property name="prefix" value="${prefix:=''}" />

<!-- Chassis -->
<xacro:macro name="p3at_chassis" params="prefix">
	<link name="${prefix}base_link">
		<inertial>
			<mass value="10.0"/>
			<origin xyz="0 0 0.177"/>
			<inertia ixx="0.3338" ixy="0.0" ixz="0.0"
				 iyy="0.4783" iyz="0.0"
				 izz="0.3338"/>
		</inertial>
		<visual>
			<origin xyz="0 0 0.177" rpy="0 0 0"/>
			<geometry name="pioneer_geom">
				<mesh filename="package://p2os_urdf/meshes/p3at_meshes/chassis.stl"/>
			</geometry>
			<material name="ChassisRed">
				<color rgba="0.851 0.0 0.0 1.0"/>
			</material>
		</visual>
		<collision>
			<origin xyz="0 0 0.177" rpy="0 0 0"/>
				<geometry>
					<mesh filename="package://p2os_urdf/meshes/p3at_meshes/chassis.stl"/>
					<!--<box size="0.4 0.28 0.17"/>-->
				</geometry>
		</collision>
	</link>
	
	<gazebo reference="${prefix}base_link">
		<material value="Gazebo/Red"/>
	</gazebo>



<!-- Top -->
	<link name="${prefix}top_plate">
		<inertial>
			<mass value="0.1"/>	
			<origin xyz="-0.025 0 -0.223"/>
			<inertia ixx="1.0" ixy="0.0" ixz="0.0"
				 iyy="1.0" iyz="0.0"
 				izz="1.0"/>
		</inertial>
		<visual>
			<origin xyz="0 0 0" rpy="0 0 0"/>
			<geometry name="pioneer_geom">
				<mesh filename="package://p2os_urdf/meshes/p3at_meshes/top.stl"/>
			</geometry>
			<material name="TopBlack">
					<color rgba="0.038 0.038 0.038 1.0"/>
			</material>
		</visual>
		<collision>
			<origin xyz="0 0 0" rpy="0 0 0"/>
			<geometry>
				<mesh filename="package://p2os_urdf/meshes/p3at_meshes/top.stl"/>
				<!--<box size="0.01 0.01 0.01"/>-->
			</geometry>
		</collision>
	</link>
	<gazebo reference="${prefix}top_plate">
		<material value="Gazebo/Black"/>
	</gazebo>

	<joint name="${prefix}base_top_joint" type="fixed">
		<origin xyz="0.003 0 0.274" rpy="0 0 0"/>
		<parent link="${prefix}base_link"/>
		<child link="${prefix}top_plate"/>
	</joint>
<!-- Front + Back Sonar -->
	<link name="${prefix}front_sonar">
		<inertial>
			<mass value="0.1"/>	
			<origin xyz="0 0 0"/>
			<inertia ixx="1.0" ixy="0.0" ixz="0.0"
				 iyy="1.0" iyz="0.0" izz="1.0"/>
		</inertial>
		<visual>
			<origin xyz="0 0 0" rpy="0 0 0"/>
			<geometry name="pioneer_geom">
				<mesh filename="package://p2os_urdf/meshes/p3at_meshes/front_sonar.stl"/>
			</geometry>
			<material name="SonarYellow">
				<color rgba="0.715 0.583 0.210 1.0"/>
			</material>
		</visual>

	</link>
	<gazebo reference="${prefix}front_sonar">
		<material value="Gazebo/Yellow"/>
	</gazebo>

	<joint name="${prefix}base_front_joint" type="fixed">
		<origin xyz="0.193 0 0.25" rpy="0 0 0"/>
		<parent link="${prefix}base_link"/>
		<child link="${prefix}front_sonar"/>
	</joint>

	<link name="${prefix}back_sonar">
		<inertial>
			<mass value="0.1"/>	
			<origin xyz="0 0 0"/>
			<inertia ixx="1.0" ixy="0.0" ixz="0.0"
				 iyy="1.0" iyz="0.0" izz="1.0"/>
		</inertial>
		<visual>
			<origin xyz="0 0 0" rpy="0 0 0"/>
			<geometry name="pioneer_geom">
				<mesh filename="package://p2os_urdf/meshes/p3at_meshes/back_sonar.stl"/>
			</geometry>
			<material name="SonarYellow">
				<color rgba="0.715 0.583 0.210 1.0"/>
			</material>
		</visual>
	</link>
	<gazebo reference="${prefix}back_sonar">
		<material value="Gazebo/Yellow"/>
	</gazebo>

	<joint name="${prefix}base_back_joint" type="fixed">
		<origin xyz="-0.187 0 0.247" rpy="0 0 0"/>
		<parent link="${prefix}base_link"/>
		<child link="${prefix}back_sonar"/>
	</joint>
</xacro:macro> <!-- End of Chassis -->

<!-- Front Axles + Wheels + Hubcaps -->
<xacro:macro name="p3at_front" params="prefix suffix reflect">
	<link name="${prefix}p3at_front_${suffix}_axle">
		<inertial>
			<mass value="0.1"/>	
			<origin xyz="0 0 0"/>
			<inertia ixx="1.0" ixy="0.0" ixz="0.0"
				 iyy="1.0" iyz="0.0" izz="1.0"/>
  	 	</inertial>
	<visual>
		<origin xyz="0 0 0" rpy="0 0 0"/>
		<geometry name="pioneer_geom">
			<mesh filename="package://p2os_urdf/meshes/p3at_meshes/axle.stl"/>
		</geometry>
		<material name="AxleGrey">
			<color rgba="0.5 0.5 0.5 1"/>
		</material>
	</visual>
	<collision>
		<origin xyz="0 0 0" rpy="0 0 0"/>
		<geometry>
			<mesh filename="package://p2os_urdf/meshes/p3at_meshes/axle.stl"/>
			<!--<box size="0.01 0.01 0.01"/>-->
		</geometry>
	</collision>
	</link>
	<gazebo reference="${prefix}p3at_front_${suffix}_axle">
		<material value="Gazebo/Grey"/>
	</gazebo>

	<joint name="${prefix}base_front_${suffix}_axle_joint" type="fixed">
		<origin xyz="0.135 ${reflect*0.156} 0.111" rpy="0 0 0"/>
		<parent link="${prefix}base_link"/>
		<child link="${prefix}p3at_front_${suffix}_axle"/>
	</joint>

	<link name="${prefix}p3at_front_${suffix}_hub">
		<inertial>
			<mass value="0.1"/>	
			<origin xyz="0 0 0"/>
			<inertia ixx="1.0" ixy="0.0" ixz="0.0"
				 iyy="1.0" iyz="0.0" izz="1.0"/>
  	 	</inertial>
	<visual>
		<origin xyz="0 0 0" rpy="0 0 0"/>
		<geometry name="pioneer_geom">
			<mesh filename="package://p2os_urdf/meshes/p3at_meshes/${suffix}_hubcap.stl"/>
		</geometry>
		<material name="HubcapYellow">
			<color rgba="1.0 0.811 0.151 1.0"/>
		</material>
	</visual>
	<collision>
		<origin xyz="0 0 0" rpy="0 0 0"/>
		<geometry>
			<mesh filename="package://p2os_urdf/meshes/p3at_meshes/${suffix}_hubcap.stl"/>
		</geometry>
	</collision>
	</link>
	<gazebo reference="${prefix}p3at_front_${suffix}_hub">
		<material value="Gazebo/Yellow"/>
	</gazebo>

	<joint name="${prefix}base_front_${suffix}_hub_joint" type="fixed">
		<origin xyz="0 ${reflect*0.041} 0" rpy="0 0 0"/>
		<parent link="${prefix}p3at_front_${suffix}_axle"/>
		<child link="${prefix}p3at_front_${suffix}_hub"/>
	</joint>

	<link name="${prefix}p3at_front_${suffix}_wheel">
		<inertial>
			<mass value="0.5"/>	
			<origin xyz="0 0 0"/>
			<inertia ixx="0.012411765597" ixy="0" ixz="0"
         iyy="0.015218160428" iyz="0" izz="0.011763977943"/>
      </inertial>
	<visual>
		<origin xyz="0 0 0" rpy="0 0 0"/>
		<geometry name="pioneer_geom">
			<mesh filename="package://p2os_urdf/meshes/p3at_meshes/wheel.stl"/>
		</geometry>
		<material name="WheelBlack">
			<color rgba="0.117 0.117 0.117 1"/>
		</material>
	</visual>
	<collision>
		<origin xyz="0 0 0" rpy="${-3.1415927/2} 0 0"/>
		<geometry>
	    <!--mesh filename="package://p2os_urdf/meshes/p3at_meshes/wheel.stl"/-->
	    <cylinder radius="0.111" length="0.075"/>
		</geometry>
	</collision>
	</link>
	<gazebo reference="${prefix}p3at_front_${suffix}_wheel">
		<material value="Gazebo/Black"/>
	</gazebo>

	<joint name="${prefix}p3at_front_${suffix}_wheel_joint" type="continuous">
  	<axis xyz="0 1 0"/>
    <anchor xyz="0 0 0"/>
    <limit effort="100" velocity="100" />
    <joint_properties damping="0.7"/>
		<origin xyz="0 0 0" rpy="0 0 0"/>
		<parent link="${prefix}p3at_front_${suffix}_hub"/>
		<child link="${prefix}p3at_front_${suffix}_wheel"/>
	</joint>
</xacro:macro>
<!-- Back Axles + Wheels + Hubcaps -->
<xacro:macro name="p3at_back" params="prefix suffix reflect">
	<link name="${prefix}p3at_back_${suffix}_axle">
		<inertial>
			<mass value="0.1"/>	
			<origin xyz="0 0 0"/>
			<inertia ixx="1.0" ixy="0.0" ixz="0.0"
				 iyy="1.0" iyz="0.0" izz="1.0"/>
  	 	</inertial>
	<visual>
		<origin xyz="0 0 0" rpy="0 0 0"/>
		<geometry name="pioneer_geom">
			<mesh filename="package://p2os_urdf/meshes/p3at_meshes/axle.stl"/>
		</geometry>
		<material name="AxleGrey">
			<color rgba="0.5 0.5 0.5 1"/>
		</material>
	</visual>
	<collision>
		<origin xyz="0 0 0" rpy="0 0 0"/>
		<geometry>
			<mesh filename="package://p2os_urdf/meshes/p3at_meshes/axle.stl"/>
			<!--<box size="0.01 0.01 0.01"/>-->
		</geometry>
	</collision>
	</link>
	<gazebo reference="${prefix}p3at_back_${suffix}_axle">
		<material value="Gazebo/Grey"/>
	</gazebo>

	<joint name="${prefix}bp3at_back_${suffix}_axle_joint" type="fixed">
		<origin xyz="-0.134 ${reflect*0.156} 0.111" rpy="0 0 0"/>
		<parent link="${prefix}base_link"/>
		<child link="${prefix}p3at_back_${suffix}_axle"/>
	</joint>


	<link name="${prefix}p3at_back_${suffix}_hub">
		<inertial>
			<mass value="0.1"/>	
			<origin xyz="0 0 0"/>
			<inertia ixx="1.0" ixy="0.0" ixz="0.0"
				 iyy="1.0" iyz="0.0" izz="1.0"/>
  	 	</inertial>
	<visual>
		<origin xyz="0 0 0" rpy="0 0 0"/>
		<geometry name="pioneer_geom">
			<mesh filename="package://p2os_urdf/meshes/p3at_meshes/${suffix}_hubcap.stl"/>
		</geometry>
		<material name="HubcapYellow"/>
	</visual>
	<collision>
		<origin xyz="0 0 0" rpy="0 0 0"/>
		<geometry>
			<mesh filename="package://p2os_urdf/meshes/p3at_meshes/${suffix}_hubcap.stl"/>
		</geometry>
	</collision>
	</link>
	<gazebo reference="${prefix}p3at_back_${suffix}_hub">
		<material value="Gazebo/Yellow"/>
	</gazebo>

	<joint name="${prefix}p3at_back_${suffix}_hub_joint" type="fixed">
		<origin xyz="-0 ${reflect*0.041} 0" rpy="0 0 0"/>
		<parent link="${prefix}p3at_back_${suffix}_axle"/>
		<child link="${prefix}p3at_back_${suffix}_hub"/>
	</joint>

	<link name="${prefix}p3at_back_${suffix}_wheel">
		<inertial>
			<mass value="0.5"/>	
			<origin xyz="0 0 0"/>
			<inertia ixx="0.012411765597" ixy="0" ixz="0"
         iyy="0.015218160428" iyz="0" izz="0.011763977943"/>
      </inertial>
	<visual>
		<origin xyz="0 0 0" rpy="0 0 0"/>
		<geometry name="pioneer_geom">
			<mesh filename="package://p2os_urdf/meshes/p3at_meshes/wheel.stl"/>
		</geometry>
		<material name="WheelBlack"/>
	</visual>
	<collision>
		<origin xyz="0 0 0" rpy="${-3.1415927/2} 0 0"/>
		<geometry>
	    <!--mesh filename="package://p2os_urdf/meshes/p3at_meshes/wheel.stl"/-->
	    <cylinder radius="0.111" length="0.075"/>
		</geometry>
	</collision>
	</link>
	<gazebo reference="${prefix}p3at_back_${suffix}_wheel">
		<material value="Gazebo/Black"/>
	</gazebo>

	<joint name="${prefix}p3at_back_${suffix}_wheel_joint" type="continuous">
	  <axis xyz="0 1 0"/>
    <anchor xyz="0 0 0"/>
    <limit effort="100" velocity="100" />
    <joint_properties damping="0.7"/>
		<origin xyz="0 0 0" rpy="0 0 0"/>
		<parent link="${prefix}p3at_back_${suffix}_hub"/>
		<child link="${prefix}p3at_back_${suffix}_wheel"/>
	</joint>
	
  <gazebo reference="${prefix}p3at_back_${suffix}_wheel">
    <kp>1000000.0</kp> <!-- kp and kd for rubber -->
    <kd>100.0</kd>
    <mu1>10.0</mu1>
    <mu2>1.0</mu2>
    <fdir1>0 1 0</fdir1> <!-- is this correct? -->
    <maxVel>1.0</maxVel>
    <minDepth>0.00</minDepth>
  </gazebo>
  
  <gazebo reference="${prefix}p3at_front_${suffix}_wheel">
    <kp>1000000.0</kp> <!-- kp and kd for rubber -->
    <kd>100.0</kd>
    <mu1>10.0</mu1>
    <mu2>1.0</mu2>
    <fdir1>0 1 0</fdir1> <!-- is this correct? -->
    <maxVel>1.0</maxVel>
    <minDepth>0.00</minDepth>
  </gazebo>

</xacro:macro>


<xacro:macro name="p3at_gazebo_ext" params="prefix">

<gazebo>
  <plugin
        filename="gz-sim-diff-drive-system"
        name="gz::sim::systems::DiffDrive">
    <updateRate>100.0</updateRate>
    <robotNamespace>/</robotNamespace>
	<num_wheel_pairs>2</num_wheel_pairs>
    <left_joint>p3at_front_left_wheel_joint</left_joint>
	<left_joint>p3at_back_left_wheel_joint</left_joint>
    <right_joint>p3at_front_right_wheel_joint</right_joint>
    <right_joint>p3at_back_right_wheel_joint</right_joint>
    <wheel_separation>0.4</wheel_separation>
    <wheel_diameter>0.215</wheel_diameter>
    <robotBaseFrame>base_link</robotBaseFrame>
    <torque>200</torque>
    <topicName>cmd_vel</topicName>
  </plugin>
</gazebo>

</xacro:macro>

</robot>
